2025-08-24 20:43:09 | ERROR | cli_coverage_test.src.cli_coverage_test.config.Config | config.py:129 | _load_config_file | ❌ Error parsing JSON config file /tmp/tmpg8k0fv35/invalid_config.json: Expecting property name enclosed in double quotes: line 1 column 3 (char 2)
2025-08-24 20:43:09 | ERROR | cli_coverage_test.src.cli_coverage_test.config.Config | config.py:119 | _load_config_file | ❌ Config file must contain a dictionary: /tmp/tmpdcu7qc9w/list_config.yaml
2025-08-24 20:43:09 | ERROR | cli_coverage_test.cli_coverage_test.core.App | core.py:158 | run | Application failed with error: Test error
2025-08-24 20:43:09 | ERROR | cli_coverage_test.cli_coverage_test.core.App | core.py:143 | _parse_env_example | Error parsing .env.example file: [Errno 2] No such file or directory: '/tmp/tmp9_3cg31o/non_existent.env'
2025-08-24 20:43:09 | ERROR | cli_coverage_test.test.with.temp | test_logger.py:369 | test_logger_with_temp_directory | Test error message
2025-08-24 20:43:09 | ERROR | cli_coverage_test.integration.test | test_logger.py:391 | test_complete_logging_workflow | Error message
2025-08-24 20:43:09 | CRITICAL | cli_coverage_test.integration.test | test_logger.py:392 | test_complete_logging_workflow | Critical message
2025-08-24 20:43:09 | ERROR | cli_coverage_test.exception.test | test_logger.py:408 | test_exception_logging | Exception occurred during test
Traceback (most recent call last):
  File "/home/runner/work/python-template/python-template/cli-coverage-test/tests/test_logger.py", line 406, in test_exception_logging
    raise RuntimeError("Test exception for logging")
RuntimeError: Test exception for logging
